[2024-08-12T06:11:47.846+0000] {taskinstance.py:1157} INFO - Dependencies all met for dep_context=non-requeueable deps ti=<TaskInstance: generate_monthly_data.predict_and_save manual__2024-08-12T06:11:43.468397+00:00 [queued]>
[2024-08-12T06:11:47.850+0000] {taskinstance.py:1157} INFO - Dependencies all met for dep_context=requeueable deps ti=<TaskInstance: generate_monthly_data.predict_and_save manual__2024-08-12T06:11:43.468397+00:00 [queued]>
[2024-08-12T06:11:47.851+0000] {taskinstance.py:1359} INFO - Starting attempt 1 of 1
[2024-08-12T06:11:47.857+0000] {taskinstance.py:1380} INFO - Executing <Task(_PythonDecoratedOperator): predict_and_save> on 2024-08-12 06:11:43.468397+00:00
[2024-08-12T06:11:47.861+0000] {standard_task_runner.py:57} INFO - Started process 9785 to run task
[2024-08-12T06:11:47.864+0000] {standard_task_runner.py:84} INFO - Running: ['***', 'tasks', 'run', 'generate_monthly_data', 'predict_and_save', 'manual__2024-08-12T06:11:43.468397+00:00', '--job-id', '120', '--raw', '--subdir', 'DAGS_FOLDER/monthly_prediction.py', '--cfg-path', '/tmp/tmpq4_oagbz']
[2024-08-12T06:11:47.865+0000] {standard_task_runner.py:85} INFO - Job 120: Subtask predict_and_save
[2024-08-12T06:11:47.913+0000] {task_command.py:415} INFO - Running <TaskInstance: generate_monthly_data.predict_and_save manual__2024-08-12T06:11:43.468397+00:00 [running]> on host fa284eed0508
[2024-08-12T06:11:48.102+0000] {taskinstance.py:1660} INFO - Exporting env vars: AIRFLOW_CTX_DAG_OWNER='***' AIRFLOW_CTX_DAG_ID='generate_monthly_data' AIRFLOW_CTX_TASK_ID='predict_and_save' AIRFLOW_CTX_EXECUTION_DATE='2024-08-12T06:11:43.468397+00:00' AIRFLOW_CTX_TRY_NUMBER='1' AIRFLOW_CTX_DAG_RUN_ID='manual__2024-08-12T06:11:43.468397+00:00'
[2024-08-12T06:11:48.175+0000] {logging_mixin.py:151} INFO - gs://mlflow-artifacts-bt/1/fab1118790cd421ab4d4d45e0b254b51/artifacts/models
[2024-08-12T06:11:48.678+0000] {logging_mixin.py:151} WARNING - Downloading artifacts:   0%|          | 0/9 [00:00<?, ?it/s]
[2024-08-12T06:11:48.679+0000] {logging_mixin.py:151} WARNING - Downloading artifacts:  11%|#1        | 1/9 [00:00<00:00, 2487.72it/s]
[2024-08-12T06:11:48.680+0000] {logging_mixin.py:151} WARNING - Downloading artifacts:  22%|##2       | 2/9 [00:00<00:00, 1824.01it/s]
[2024-08-12T06:11:48.728+0000] {logging_mixin.py:151} WARNING - Downloading artifacts:  33%|###3      | 3/9 [00:00<00:00, 60.70it/s]  
[2024-08-12T06:11:48.753+0000] {logging_mixin.py:151} WARNING - Downloading artifacts:  44%|####4     | 4/9 [00:00<00:00, 54.18it/s]
[2024-08-12T06:11:48.769+0000] {logging_mixin.py:151} WARNING - Downloading artifacts:  56%|#####5    | 5/9 [00:00<00:00, 55.54it/s]
[2024-08-12T06:11:48.771+0000] {logging_mixin.py:151} WARNING - Downloading artifacts:  67%|######6   | 6/9 [00:00<00:00, 64.92it/s]
[2024-08-12T06:11:48.779+0000] {logging_mixin.py:151} WARNING - Downloading artifacts:  78%|#######7  | 7/9 [00:00<00:00, 69.84it/s]
[2024-08-12T06:11:48.780+0000] {logging_mixin.py:151} WARNING - Downloading artifacts:  78%|#######7  | 7/9 [00:00<00:00, 69.84it/s]
[2024-08-12T06:11:48.866+0000] {logging_mixin.py:151} WARNING - Downloading artifacts:  89%|########8 | 8/9 [00:00<00:00, 69.84it/s]
[2024-08-12T06:11:49.730+0000] {logging_mixin.py:151} WARNING - Downloading artifacts: 100%|##########| 9/9 [00:01<00:00, 69.84it/s]
[2024-08-12T06:11:49.730+0000] {logging_mixin.py:151} WARNING - Downloading artifacts: 100%|##########| 9/9 [00:01<00:00,  8.56it/s]
[2024-08-12T06:11:49.961+0000] {logging_mixin.py:151} INFO - RandomForestClassifier version 1 loaded
[2024-08-12T06:14:04.403+0000] {local_task_job_runner.py:294} WARNING - State of this instance has been externally set to None. Terminating instance.
[2024-08-12T06:14:04.409+0000] {process_utils.py:131} INFO - Sending 15 to group 9785. PIDs of all processes in the group: [9785]
[2024-08-12T06:14:04.409+0000] {process_utils.py:86} INFO - Sending the signal 15 to group 9785
[2024-08-12T06:14:04.410+0000] {taskinstance.py:1630} ERROR - Received SIGTERM. Terminating subprocesses.
[2024-08-12T06:14:04.426+0000] {taskinstance.py:1935} ERROR - Task failed with exception
Traceback (most recent call last):
  File "/home/airflow/.local/lib/python3.8/site-packages/airflow/decorators/base.py", line 221, in execute
    return_value = super().execute(context)
  File "/home/airflow/.local/lib/python3.8/site-packages/airflow/operators/python.py", line 192, in execute
    return_value = self.execute_callable()
  File "/home/airflow/.local/lib/python3.8/site-packages/airflow/operators/python.py", line 209, in execute_callable
    return self.python_callable(*self.op_args, **self.op_kwargs)
  File "/opt/airflow/dags/monthly_prediction.py", line 40, in predict_and_save
    output_path = f'gs://scoring-artifacts-bt/predictions_{month_end}.csv'
  File "/home/airflow/.local/lib/python3.8/site-packages/pandas/core/generic.py", line 3772, in to_csv
    return DataFrameRenderer(formatter).to_csv(
  File "/home/airflow/.local/lib/python3.8/site-packages/pandas/io/formats/format.py", line 1186, in to_csv
    csv_formatter.save()
  File "/home/airflow/.local/lib/python3.8/site-packages/pandas/io/formats/csvs.py", line 240, in save
    with get_handle(
  File "/home/airflow/.local/lib/python3.8/site-packages/pandas/io/common.py", line 716, in get_handle
    ioargs = _get_filepath_or_buffer(
  File "/home/airflow/.local/lib/python3.8/site-packages/pandas/io/common.py", line 414, in _get_filepath_or_buffer
    file_obj = fsspec.open(
  File "/home/airflow/.local/lib/python3.8/site-packages/fsspec/core.py", line 484, in open
    out = open_files(
  File "/home/airflow/.local/lib/python3.8/site-packages/fsspec/core.py", line 310, in open_files
    fs.makedirs(parent, exist_ok=True)
  File "/home/airflow/.local/lib/python3.8/site-packages/fsspec/asyn.py", line 118, in wrapper
    return sync(self.loop, func, *args, **kwargs)
  File "/home/airflow/.local/lib/python3.8/site-packages/fsspec/asyn.py", line 91, in sync
    if event.wait(1):
  File "/usr/local/lib/python3.8/threading.py", line 558, in wait
    signaled = self._cond.wait(timeout)
  File "/usr/local/lib/python3.8/threading.py", line 306, in wait
    gotit = waiter.acquire(True, timeout)
  File "/home/airflow/.local/lib/python3.8/site-packages/airflow/models/taskinstance.py", line 1632, in signal_handler
    raise AirflowException("Task received SIGTERM signal")
airflow.exceptions.AirflowException: Task received SIGTERM signal
[2024-08-12T06:14:04.441+0000] {taskinstance.py:1398} INFO - Marking task as FAILED. dag_id=generate_monthly_data, task_id=predict_and_save, execution_date=20240812T061143, start_date=20240812T061147, end_date=20240812T061404
[2024-08-12T06:14:04.453+0000] {standard_task_runner.py:104} ERROR - Failed to execute job 120 for task predict_and_save ((psycopg2.errors.ForeignKeyViolation) insert or update on table "task_fail" violates foreign key constraint "task_fail_ti_fkey"
DETAIL:  Key (dag_id, task_id, run_id, map_index)=(generate_monthly_data, predict_and_save, manual__2024-08-12T06:11:43.468397+00:00, -1) is not present in table "task_instance".

[SQL: INSERT INTO task_fail (task_id, dag_id, run_id, map_index, start_date, end_date, duration) VALUES (%(task_id)s, %(dag_id)s, %(run_id)s, %(map_index)s, %(start_date)s, %(end_date)s, %(duration)s) RETURNING task_fail.id]
[parameters: {'task_id': 'predict_and_save', 'dag_id': 'generate_monthly_data', 'run_id': 'manual__2024-08-12T06:11:43.468397+00:00', 'map_index': -1, 'start_date': datetime.datetime(2024, 8, 12, 6, 11, 47, 847103, tzinfo=Timezone('UTC')), 'end_date': datetime.datetime(2024, 8, 12, 6, 14, 4, 438247, tzinfo=Timezone('UTC')), 'duration': 136}]
(Background on this error at: https://sqlalche.me/e/14/gkpj); 9785)
[2024-08-12T06:14:04.466+0000] {process_utils.py:79} INFO - Process psutil.Process(pid=9785, status='terminated', exitcode=1, started='06:11:47') (9785) terminated with exit code 1
