[2024-08-12T06:06:43.774+0000] {taskinstance.py:1157} INFO - Dependencies all met for dep_context=non-requeueable deps ti=<TaskInstance: generate_monthly_data.predict_and_save manual__2024-08-12T06:06:39.205487+00:00 [queued]>
[2024-08-12T06:06:43.778+0000] {taskinstance.py:1157} INFO - Dependencies all met for dep_context=requeueable deps ti=<TaskInstance: generate_monthly_data.predict_and_save manual__2024-08-12T06:06:39.205487+00:00 [queued]>
[2024-08-12T06:06:43.778+0000] {taskinstance.py:1359} INFO - Starting attempt 1 of 1
[2024-08-12T06:06:43.783+0000] {taskinstance.py:1380} INFO - Executing <Task(_PythonDecoratedOperator): predict_and_save> on 2024-08-12 06:06:39.205487+00:00
[2024-08-12T06:06:43.787+0000] {standard_task_runner.py:57} INFO - Started process 8343 to run task
[2024-08-12T06:06:43.789+0000] {standard_task_runner.py:84} INFO - Running: ['***', 'tasks', 'run', 'generate_monthly_data', 'predict_and_save', 'manual__2024-08-12T06:06:39.205487+00:00', '--job-id', '115', '--raw', '--subdir', 'DAGS_FOLDER/monthly_prediction.py', '--cfg-path', '/tmp/tmpv5tr7fui']
[2024-08-12T06:06:43.790+0000] {standard_task_runner.py:85} INFO - Job 115: Subtask predict_and_save
[2024-08-12T06:06:43.817+0000] {task_command.py:415} INFO - Running <TaskInstance: generate_monthly_data.predict_and_save manual__2024-08-12T06:06:39.205487+00:00 [running]> on host fa284eed0508
[2024-08-12T06:06:43.908+0000] {taskinstance.py:1660} INFO - Exporting env vars: AIRFLOW_CTX_DAG_OWNER='***' AIRFLOW_CTX_DAG_ID='generate_monthly_data' AIRFLOW_CTX_TASK_ID='predict_and_save' AIRFLOW_CTX_EXECUTION_DATE='2024-08-12T06:06:39.205487+00:00' AIRFLOW_CTX_TRY_NUMBER='1' AIRFLOW_CTX_DAG_RUN_ID='manual__2024-08-12T06:06:39.205487+00:00'
[2024-08-12T06:06:43.939+0000] {logging_mixin.py:151} INFO - gs://mlflow-artifacts-bt/1/fab1118790cd421ab4d4d45e0b254b51/artifacts/models
[2024-08-12T06:06:44.441+0000] {logging_mixin.py:151} WARNING - Downloading artifacts:   0%|          | 0/9 [00:00<?, ?it/s]
[2024-08-12T06:06:44.441+0000] {logging_mixin.py:151} WARNING - Downloading artifacts:  11%|#1        | 1/9 [00:00<00:00, 9258.95it/s]
[2024-08-12T06:06:44.441+0000] {logging_mixin.py:151} WARNING - Downloading artifacts:  22%|##2       | 2/9 [00:00<00:00, 5242.88it/s]
[2024-08-12T06:06:44.468+0000] {logging_mixin.py:151} WARNING - Downloading artifacts:  33%|###3      | 3/9 [00:00<00:00, 113.59it/s] 
[2024-08-12T06:06:44.469+0000] {logging_mixin.py:151} WARNING - Downloading artifacts:  44%|####4     | 4/9 [00:00<00:00, 143.44it/s]
[2024-08-12T06:06:44.488+0000] {logging_mixin.py:151} WARNING - Downloading artifacts:  56%|#####5    | 5/9 [00:00<00:00, 106.63it/s]
[2024-08-12T06:06:44.502+0000] {logging_mixin.py:151} WARNING - Downloading artifacts:  67%|######6   | 6/9 [00:00<00:00, 99.36it/s] 
[2024-08-12T06:06:44.510+0000] {logging_mixin.py:151} WARNING - Downloading artifacts:  78%|#######7  | 7/9 [00:00<00:00, 102.42it/s]
[2024-08-12T06:06:44.518+0000] {logging_mixin.py:151} WARNING - Downloading artifacts:  89%|########8 | 8/9 [00:00<00:00, 104.19it/s]
[2024-08-12T06:06:45.462+0000] {logging_mixin.py:151} WARNING - Downloading artifacts: 100%|##########| 9/9 [00:01<00:00,  8.82it/s] 
[2024-08-12T06:06:45.462+0000] {logging_mixin.py:151} WARNING - Downloading artifacts: 100%|##########| 9/9 [00:01<00:00,  8.82it/s]
[2024-08-12T06:06:45.463+0000] {logging_mixin.py:151} WARNING - Downloading artifacts: 100%|##########| 9/9 [00:01<00:00,  8.81it/s]
[2024-08-12T06:06:45.619+0000] {logging_mixin.py:151} INFO - RandomForestClassifier version 1 loaded
[2024-08-12T06:11:46.805+0000] {local_task_job_runner.py:294} WARNING - State of this instance has been externally set to None. Terminating instance.
[2024-08-12T06:11:46.814+0000] {process_utils.py:131} INFO - Sending 15 to group 8343. PIDs of all processes in the group: [8343]
[2024-08-12T06:11:46.815+0000] {process_utils.py:86} INFO - Sending the signal 15 to group 8343
[2024-08-12T06:11:46.816+0000] {taskinstance.py:1630} ERROR - Received SIGTERM. Terminating subprocesses.
[2024-08-12T06:11:46.836+0000] {taskinstance.py:1935} ERROR - Task failed with exception
Traceback (most recent call last):
  File "/home/airflow/.local/lib/python3.8/site-packages/airflow/decorators/base.py", line 221, in execute
    return_value = super().execute(context)
  File "/home/airflow/.local/lib/python3.8/site-packages/airflow/operators/python.py", line 192, in execute
    return_value = self.execute_callable()
  File "/home/airflow/.local/lib/python3.8/site-packages/airflow/operators/python.py", line 209, in execute_callable
    return self.python_callable(*self.op_args, **self.op_kwargs)
  File "/opt/airflow/dags/monthly_prediction.py", line 37, in predict_and_save
    df['prediction'] = prediction
  File "/home/airflow/.local/lib/python3.8/site-packages/pandas/core/generic.py", line 3772, in to_csv
    return DataFrameRenderer(formatter).to_csv(
  File "/home/airflow/.local/lib/python3.8/site-packages/pandas/io/formats/format.py", line 1186, in to_csv
    csv_formatter.save()
  File "/home/airflow/.local/lib/python3.8/site-packages/pandas/io/formats/csvs.py", line 240, in save
    with get_handle(
  File "/home/airflow/.local/lib/python3.8/site-packages/pandas/io/common.py", line 716, in get_handle
    ioargs = _get_filepath_or_buffer(
  File "/home/airflow/.local/lib/python3.8/site-packages/pandas/io/common.py", line 414, in _get_filepath_or_buffer
    file_obj = fsspec.open(
  File "/home/airflow/.local/lib/python3.8/site-packages/fsspec/core.py", line 484, in open
    out = open_files(
  File "/home/airflow/.local/lib/python3.8/site-packages/fsspec/core.py", line 310, in open_files
    fs.makedirs(parent, exist_ok=True)
  File "/home/airflow/.local/lib/python3.8/site-packages/fsspec/asyn.py", line 118, in wrapper
    return sync(self.loop, func, *args, **kwargs)
  File "/home/airflow/.local/lib/python3.8/site-packages/fsspec/asyn.py", line 91, in sync
    if event.wait(1):
  File "/usr/local/lib/python3.8/threading.py", line 558, in wait
    signaled = self._cond.wait(timeout)
  File "/usr/local/lib/python3.8/threading.py", line 306, in wait
    gotit = waiter.acquire(True, timeout)
  File "/home/airflow/.local/lib/python3.8/site-packages/airflow/models/taskinstance.py", line 1632, in signal_handler
    raise AirflowException("Task received SIGTERM signal")
airflow.exceptions.AirflowException: Task received SIGTERM signal
[2024-08-12T06:11:46.847+0000] {taskinstance.py:1398} INFO - Marking task as FAILED. dag_id=generate_monthly_data, task_id=predict_and_save, execution_date=20240812T060639, start_date=20240812T060643, end_date=20240812T061146
[2024-08-12T06:11:46.861+0000] {standard_task_runner.py:104} ERROR - Failed to execute job 115 for task predict_and_save ((psycopg2.errors.ForeignKeyViolation) insert or update on table "task_fail" violates foreign key constraint "task_fail_ti_fkey"
DETAIL:  Key (dag_id, task_id, run_id, map_index)=(generate_monthly_data, predict_and_save, manual__2024-08-12T06:06:39.205487+00:00, -1) is not present in table "task_instance".

[SQL: INSERT INTO task_fail (task_id, dag_id, run_id, map_index, start_date, end_date, duration) VALUES (%(task_id)s, %(dag_id)s, %(run_id)s, %(map_index)s, %(start_date)s, %(end_date)s, %(duration)s) RETURNING task_fail.id]
[parameters: {'task_id': 'predict_and_save', 'dag_id': 'generate_monthly_data', 'run_id': 'manual__2024-08-12T06:06:39.205487+00:00', 'map_index': -1, 'start_date': datetime.datetime(2024, 8, 12, 6, 6, 43, 774983, tzinfo=Timezone('UTC')), 'end_date': datetime.datetime(2024, 8, 12, 6, 11, 46, 845836, tzinfo=Timezone('UTC')), 'duration': 303}]
(Background on this error at: https://sqlalche.me/e/14/gkpj); 8343)
[2024-08-12T06:11:46.873+0000] {process_utils.py:79} INFO - Process psutil.Process(pid=8343, status='terminated', exitcode=1, started='06:06:43') (8343) terminated with exit code 1
