[2024-08-12T05:59:47.188+0000] {taskinstance.py:1157} INFO - Dependencies all met for dep_context=non-requeueable deps ti=<TaskInstance: generate_monthly_data.predict_and_save manual__2024-08-12T05:59:42.397647+00:00 [queued]>
[2024-08-12T05:59:47.191+0000] {taskinstance.py:1157} INFO - Dependencies all met for dep_context=requeueable deps ti=<TaskInstance: generate_monthly_data.predict_and_save manual__2024-08-12T05:59:42.397647+00:00 [queued]>
[2024-08-12T05:59:47.192+0000] {taskinstance.py:1359} INFO - Starting attempt 1 of 1
[2024-08-12T05:59:47.197+0000] {taskinstance.py:1380} INFO - Executing <Task(_PythonDecoratedOperator): predict_and_save> on 2024-08-12 05:59:42.397647+00:00
[2024-08-12T05:59:47.201+0000] {standard_task_runner.py:57} INFO - Started process 6645 to run task
[2024-08-12T05:59:47.203+0000] {standard_task_runner.py:84} INFO - Running: ['***', 'tasks', 'run', 'generate_monthly_data', 'predict_and_save', 'manual__2024-08-12T05:59:42.397647+00:00', '--job-id', '97', '--raw', '--subdir', 'DAGS_FOLDER/monthly_prediction.py', '--cfg-path', '/tmp/tmps2m1lgs7']
[2024-08-12T05:59:47.204+0000] {standard_task_runner.py:85} INFO - Job 97: Subtask predict_and_save
[2024-08-12T05:59:47.243+0000] {task_command.py:415} INFO - Running <TaskInstance: generate_monthly_data.predict_and_save manual__2024-08-12T05:59:42.397647+00:00 [running]> on host fa284eed0508
[2024-08-12T05:59:47.369+0000] {taskinstance.py:1660} INFO - Exporting env vars: AIRFLOW_CTX_DAG_OWNER='***' AIRFLOW_CTX_DAG_ID='generate_monthly_data' AIRFLOW_CTX_TASK_ID='predict_and_save' AIRFLOW_CTX_EXECUTION_DATE='2024-08-12T05:59:42.397647+00:00' AIRFLOW_CTX_TRY_NUMBER='1' AIRFLOW_CTX_DAG_RUN_ID='manual__2024-08-12T05:59:42.397647+00:00'
[2024-08-12T05:59:47.414+0000] {logging_mixin.py:151} INFO - gs://mlflow-artifacts-bt/1/fab1118790cd421ab4d4d45e0b254b51/artifacts/models
[2024-08-12T05:59:47.834+0000] {logging_mixin.py:151} WARNING - Downloading artifacts:   0%|          | 0/9 [00:00<?, ?it/s]
[2024-08-12T05:59:47.835+0000] {logging_mixin.py:151} WARNING - Downloading artifacts:  11%|#1        | 1/9 [00:00<00:00, 11008.67it/s]
[2024-08-12T05:59:47.836+0000] {logging_mixin.py:151} WARNING - Downloading artifacts:  22%|##2       | 2/9 [00:00<00:00, 1510.37it/s] 
[2024-08-12T05:59:47.874+0000] {logging_mixin.py:151} WARNING - Downloading artifacts:  33%|###3      | 3/9 [00:00<00:00, 75.98it/s]  
[2024-08-12T05:59:47.921+0000] {logging_mixin.py:151} WARNING - Downloading artifacts:  44%|####4     | 4/9 [00:00<00:00, 46.59it/s]
[2024-08-12T05:59:47.921+0000] {logging_mixin.py:151} WARNING - Downloading artifacts:  56%|#####5    | 5/9 [00:00<00:00, 58.00it/s]
[2024-08-12T05:59:47.922+0000] {logging_mixin.py:151} WARNING - Downloading artifacts:  67%|######6   | 6/9 [00:00<00:00, 68.69it/s]
[2024-08-12T05:59:47.937+0000] {logging_mixin.py:151} WARNING - Downloading artifacts:  78%|#######7  | 7/9 [00:00<00:00, 68.54it/s]
[2024-08-12T05:59:47.938+0000] {logging_mixin.py:151} WARNING - Downloading artifacts:  78%|#######7  | 7/9 [00:00<00:00, 68.54it/s]
[2024-08-12T05:59:47.977+0000] {logging_mixin.py:151} WARNING - Downloading artifacts:  89%|########8 | 8/9 [00:00<00:00, 68.54it/s]
[2024-08-12T05:59:48.876+0000] {logging_mixin.py:151} WARNING - Downloading artifacts: 100%|##########| 9/9 [00:01<00:00, 68.54it/s]
[2024-08-12T05:59:48.877+0000] {logging_mixin.py:151} WARNING - Downloading artifacts: 100%|##########| 9/9 [00:01<00:00,  8.64it/s]
[2024-08-12T05:59:49.057+0000] {logging_mixin.py:151} INFO - RandomForestClassifier version 1 loaded
[2024-08-12T06:00:52.933+0000] {local_task_job_runner.py:294} WARNING - State of this instance has been externally set to None. Terminating instance.
[2024-08-12T06:00:53.014+0000] {process_utils.py:131} INFO - Sending 15 to group 6645. PIDs of all processes in the group: [6645]
[2024-08-12T06:00:53.014+0000] {process_utils.py:86} INFO - Sending the signal 15 to group 6645
[2024-08-12T06:00:53.020+0000] {taskinstance.py:1630} ERROR - Received SIGTERM. Terminating subprocesses.
[2024-08-12T06:00:53.149+0000] {taskinstance.py:1935} ERROR - Task failed with exception
Traceback (most recent call last):
  File "/home/airflow/.local/lib/python3.8/site-packages/airflow/decorators/base.py", line 221, in execute
    return_value = super().execute(context)
  File "/home/airflow/.local/lib/python3.8/site-packages/airflow/operators/python.py", line 192, in execute
    return_value = self.execute_callable()
  File "/home/airflow/.local/lib/python3.8/site-packages/airflow/operators/python.py", line 209, in execute_callable
    return self.python_callable(*self.op_args, **self.op_kwargs)
  File "/opt/airflow/dags/monthly_prediction.py", line 37, in predict_and_save
    df.to_csv(output_path, index=False)
  File "/home/airflow/.local/lib/python3.8/site-packages/pandas/core/generic.py", line 3772, in to_csv
    return DataFrameRenderer(formatter).to_csv(
  File "/home/airflow/.local/lib/python3.8/site-packages/pandas/io/formats/format.py", line 1186, in to_csv
    csv_formatter.save()
  File "/home/airflow/.local/lib/python3.8/site-packages/pandas/io/formats/csvs.py", line 240, in save
    with get_handle(
  File "/home/airflow/.local/lib/python3.8/site-packages/pandas/io/common.py", line 716, in get_handle
    ioargs = _get_filepath_or_buffer(
  File "/home/airflow/.local/lib/python3.8/site-packages/pandas/io/common.py", line 414, in _get_filepath_or_buffer
    file_obj = fsspec.open(
  File "/home/airflow/.local/lib/python3.8/site-packages/fsspec/core.py", line 484, in open
    out = open_files(
  File "/home/airflow/.local/lib/python3.8/site-packages/fsspec/core.py", line 310, in open_files
    fs.makedirs(parent, exist_ok=True)
  File "/home/airflow/.local/lib/python3.8/site-packages/fsspec/asyn.py", line 118, in wrapper
    return sync(self.loop, func, *args, **kwargs)
  File "/home/airflow/.local/lib/python3.8/site-packages/fsspec/asyn.py", line 91, in sync
    if event.wait(1):
  File "/usr/local/lib/python3.8/threading.py", line 558, in wait
    signaled = self._cond.wait(timeout)
  File "/usr/local/lib/python3.8/threading.py", line 306, in wait
    gotit = waiter.acquire(True, timeout)
  File "/home/airflow/.local/lib/python3.8/site-packages/airflow/models/taskinstance.py", line 1632, in signal_handler
    raise AirflowException("Task received SIGTERM signal")
airflow.exceptions.AirflowException: Task received SIGTERM signal
[2024-08-12T06:00:53.181+0000] {taskinstance.py:1398} INFO - Marking task as FAILED. dag_id=generate_monthly_data, task_id=predict_and_save, execution_date=20240812T055942, start_date=20240812T055947, end_date=20240812T060053
[2024-08-12T06:00:53.202+0000] {standard_task_runner.py:104} ERROR - Failed to execute job 97 for task predict_and_save ((psycopg2.errors.ForeignKeyViolation) insert or update on table "task_fail" violates foreign key constraint "task_fail_ti_fkey"
DETAIL:  Key (dag_id, task_id, run_id, map_index)=(generate_monthly_data, predict_and_save, manual__2024-08-12T05:59:42.397647+00:00, -1) is not present in table "task_instance".

[SQL: INSERT INTO task_fail (task_id, dag_id, run_id, map_index, start_date, end_date, duration) VALUES (%(task_id)s, %(dag_id)s, %(run_id)s, %(map_index)s, %(start_date)s, %(end_date)s, %(duration)s) RETURNING task_fail.id]
[parameters: {'task_id': 'predict_and_save', 'dag_id': 'generate_monthly_data', 'run_id': 'manual__2024-08-12T05:59:42.397647+00:00', 'map_index': -1, 'start_date': datetime.datetime(2024, 8, 12, 5, 59, 47, 188536, tzinfo=Timezone('UTC')), 'end_date': datetime.datetime(2024, 8, 12, 6, 0, 53, 178966, tzinfo=Timezone('UTC')), 'duration': 65}]
(Background on this error at: https://sqlalche.me/e/14/gkpj); 6645)
[2024-08-12T06:00:53.253+0000] {process_utils.py:79} INFO - Process psutil.Process(pid=6645, status='terminated', exitcode=1, started='05:59:46') (6645) terminated with exit code 1
