[2024-08-12T03:42:20.594+0000] {taskinstance.py:1157} INFO - Dependencies all met for dep_context=non-requeueable deps ti=<TaskInstance: quarterly_retrain.load_transform_data manual__2024-08-12T03:42:18.784537+00:00 [queued]>
[2024-08-12T03:42:20.600+0000] {taskinstance.py:1157} INFO - Dependencies all met for dep_context=requeueable deps ti=<TaskInstance: quarterly_retrain.load_transform_data manual__2024-08-12T03:42:18.784537+00:00 [queued]>
[2024-08-12T03:42:20.600+0000] {taskinstance.py:1359} INFO - Starting attempt 1 of 1
[2024-08-12T03:42:20.606+0000] {taskinstance.py:1380} INFO - Executing <Task(_PythonDecoratedOperator): load_transform_data> on 2024-08-12 03:42:18.784537+00:00
[2024-08-12T03:42:20.612+0000] {standard_task_runner.py:57} INFO - Started process 5876 to run task
[2024-08-12T03:42:20.615+0000] {standard_task_runner.py:84} INFO - Running: ['***', 'tasks', 'run', 'quarterly_retrain', 'load_transform_data', 'manual__2024-08-12T03:42:18.784537+00:00', '--job-id', '35', '--raw', '--subdir', 'DAGS_FOLDER/quarterly_retrain.py', '--cfg-path', '/tmp/tmpqg0odshe']
[2024-08-12T03:42:20.616+0000] {standard_task_runner.py:85} INFO - Job 35: Subtask load_transform_data
[2024-08-12T03:42:20.660+0000] {task_command.py:415} INFO - Running <TaskInstance: quarterly_retrain.load_transform_data manual__2024-08-12T03:42:18.784537+00:00 [running]> on host f7c751ddefa9
[2024-08-12T03:42:20.704+0000] {taskinstance.py:1660} INFO - Exporting env vars: AIRFLOW_CTX_DAG_OWNER='***' AIRFLOW_CTX_DAG_ID='quarterly_retrain' AIRFLOW_CTX_TASK_ID='load_transform_data' AIRFLOW_CTX_EXECUTION_DATE='2024-08-12T03:42:18.784537+00:00' AIRFLOW_CTX_TRY_NUMBER='1' AIRFLOW_CTX_DAG_RUN_ID='manual__2024-08-12T03:42:18.784537+00:00'
[2024-08-12T03:42:21.138+0000] {taskinstance.py:1935} ERROR - Task failed with exception
Traceback (most recent call last):
  File "/home/airflow/.local/lib/python3.8/site-packages/airflow/decorators/base.py", line 221, in execute
    return_value = super().execute(context)
  File "/home/airflow/.local/lib/python3.8/site-packages/airflow/operators/python.py", line 192, in execute
    return_value = self.execute_callable()
  File "/home/airflow/.local/lib/python3.8/site-packages/airflow/operators/python.py", line 209, in execute_callable
    return self.python_callable(*self.op_args, **self.op_kwargs)
  File "/opt/airflow/dags/quarterly_retrain.py", line 131, in load_transform_data
    X_train = data['X_train']
TypeError: tuple indices must be integers or slices, not str
[2024-08-12T03:42:21.152+0000] {taskinstance.py:1398} INFO - Marking task as FAILED. dag_id=quarterly_retrain, task_id=load_transform_data, execution_date=20240812T034218, start_date=20240812T034220, end_date=20240812T034221
[2024-08-12T03:42:21.160+0000] {standard_task_runner.py:104} ERROR - Failed to execute job 35 for task load_transform_data (tuple indices must be integers or slices, not str; 5876)
[2024-08-12T03:42:21.206+0000] {local_task_job_runner.py:228} INFO - Task exited with return code 1
[2024-08-12T03:42:21.216+0000] {taskinstance.py:2776} INFO - 0 downstream tasks scheduled from follow-on schedule check
