[2024-08-12T18:04:46.542+0000] {taskinstance.py:1157} INFO - Dependencies all met for dep_context=non-requeueable deps ti=<TaskInstance: monthly_monitor.create_db scheduled__2024-02-01T00:00:00+00:00 [queued]>
[2024-08-12T18:04:46.649+0000] {taskinstance.py:1157} INFO - Dependencies all met for dep_context=requeueable deps ti=<TaskInstance: monthly_monitor.create_db scheduled__2024-02-01T00:00:00+00:00 [queued]>
[2024-08-12T18:04:46.654+0000] {taskinstance.py:1359} INFO - Starting attempt 1 of 1
[2024-08-12T18:04:46.719+0000] {taskinstance.py:1380} INFO - Executing <Task(_PythonDecoratedOperator): create_db> on 2024-02-01 00:00:00+00:00
[2024-08-12T18:04:46.852+0000] {standard_task_runner.py:57} INFO - Started process 7836 to run task
[2024-08-12T18:04:46.899+0000] {standard_task_runner.py:84} INFO - Running: ['***', 'tasks', 'run', 'monthly_monitor', 'create_db', 'scheduled__2024-02-01T00:00:00+00:00', '--job-id', '201', '--raw', '--subdir', 'DAGS_FOLDER/monitor.py', '--cfg-path', '/tmp/tmppxpw4bmb']
[2024-08-12T18:04:46.940+0000] {standard_task_runner.py:85} INFO - Job 201: Subtask create_db
[2024-08-12T18:04:47.287+0000] {task_command.py:415} INFO - Running <TaskInstance: monthly_monitor.create_db scheduled__2024-02-01T00:00:00+00:00 [running]> on host a9166c5dc5ae
[2024-08-12T18:04:47.659+0000] {taskinstance.py:1660} INFO - Exporting env vars: AIRFLOW_CTX_DAG_OWNER='***' AIRFLOW_CTX_DAG_ID='monthly_monitor' AIRFLOW_CTX_TASK_ID='create_db' AIRFLOW_CTX_EXECUTION_DATE='2024-02-01T00:00:00+00:00' AIRFLOW_CTX_TRY_NUMBER='1' AIRFLOW_CTX_DAG_RUN_ID='scheduled__2024-02-01T00:00:00+00:00'
[2024-08-12T18:04:47.719+0000] {taskinstance.py:1935} ERROR - Task failed with exception
Traceback (most recent call last):
  File "/home/airflow/.local/lib/python3.8/site-packages/airflow/decorators/base.py", line 221, in execute
    return_value = super().execute(context)
  File "/home/airflow/.local/lib/python3.8/site-packages/airflow/operators/python.py", line 192, in execute
    return_value = self.execute_callable()
  File "/home/airflow/.local/lib/python3.8/site-packages/airflow/operators/python.py", line 209, in execute_callable
    return self.python_callable(*self.op_args, **self.op_kwargs)
  File "/opt/airflow/dags/monitor.py", line 31, in create_db
    conn = psycopg2.connect(**conn_params)
  File "/home/airflow/.local/lib/python3.8/site-packages/psycopg2/__init__.py", line 122, in connect
    conn = _connect(dsn, connection_factory=connection_factory, **kwasync)
psycopg2.OperationalError: connection to server at "localhost" (127.0.0.1), port 5432 failed: Connection refused
	Is the server running on that host and accepting TCP/IP connections?
connection to server at "localhost" (::1), port 5432 failed: Cannot assign requested address
	Is the server running on that host and accepting TCP/IP connections?

[2024-08-12T18:04:47.826+0000] {taskinstance.py:1398} INFO - Marking task as FAILED. dag_id=monthly_monitor, task_id=create_db, execution_date=20240201T000000, start_date=20240812T180446, end_date=20240812T180447
[2024-08-12T18:04:47.900+0000] {standard_task_runner.py:104} ERROR - Failed to execute job 201 for task create_db (connection to server at "localhost" (127.0.0.1), port 5432 failed: Connection refused
	Is the server running on that host and accepting TCP/IP connections?
connection to server at "localhost" (::1), port 5432 failed: Cannot assign requested address
	Is the server running on that host and accepting TCP/IP connections?
; 7836)
[2024-08-12T18:04:48.077+0000] {local_task_job_runner.py:228} INFO - Task exited with return code 1
[2024-08-12T18:04:48.239+0000] {taskinstance.py:2776} INFO - 0 downstream tasks scheduled from follow-on schedule check
