[2024-08-12T00:19:02.866+0000] {taskinstance.py:1157} INFO - Dependencies all met for dep_context=non-requeueable deps ti=<TaskInstance: quarterly_retrain.load_transform_data manual__2024-08-12T00:18:59.670125+00:00 [queued]>
[2024-08-12T00:19:02.872+0000] {taskinstance.py:1157} INFO - Dependencies all met for dep_context=requeueable deps ti=<TaskInstance: quarterly_retrain.load_transform_data manual__2024-08-12T00:18:59.670125+00:00 [queued]>
[2024-08-12T00:19:02.875+0000] {taskinstance.py:1359} INFO - Starting attempt 1 of 1
[2024-08-12T00:19:02.888+0000] {taskinstance.py:1380} INFO - Executing <Task(_PythonDecoratedOperator): load_transform_data> on 2024-08-12 00:18:59.670125+00:00
[2024-08-12T00:19:02.912+0000] {standard_task_runner.py:57} INFO - Started process 2353 to run task
[2024-08-12T00:19:02.916+0000] {standard_task_runner.py:84} INFO - Running: ['***', 'tasks', 'run', 'quarterly_retrain', 'load_transform_data', 'manual__2024-08-12T00:18:59.670125+00:00', '--job-id', '8', '--raw', '--subdir', 'DAGS_FOLDER/quarterly_retrain.py', '--cfg-path', '/tmp/tmp5u8o0n0_']
[2024-08-12T00:19:02.919+0000] {standard_task_runner.py:85} INFO - Job 8: Subtask load_transform_data
[2024-08-12T00:19:02.966+0000] {task_command.py:415} INFO - Running <TaskInstance: quarterly_retrain.load_transform_data manual__2024-08-12T00:18:59.670125+00:00 [running]> on host 82ec9a7413d7
[2024-08-12T00:19:03.043+0000] {taskinstance.py:1660} INFO - Exporting env vars: AIRFLOW_CTX_DAG_OWNER='***' AIRFLOW_CTX_DAG_ID='quarterly_retrain' AIRFLOW_CTX_TASK_ID='load_transform_data' AIRFLOW_CTX_EXECUTION_DATE='2024-08-12T00:18:59.670125+00:00' AIRFLOW_CTX_TRY_NUMBER='1' AIRFLOW_CTX_DAG_RUN_ID='manual__2024-08-12T00:18:59.670125+00:00'
[2024-08-12T00:19:03.071+0000] {taskinstance.py:1935} ERROR - Task failed with exception
Traceback (most recent call last):
  File "/home/airflow/.local/lib/python3.8/site-packages/fsspec/registry.py", line 242, in get_filesystem_class
    register_implementation(protocol, _import_class(bit["class"]))
  File "/home/airflow/.local/lib/python3.8/site-packages/fsspec/registry.py", line 277, in _import_class
    mod = importlib.import_module(mod)
  File "/usr/local/lib/python3.8/importlib/__init__.py", line 127, in import_module
    return _bootstrap._gcd_import(name[level:], package, level)
  File "<frozen importlib._bootstrap>", line 1014, in _gcd_import
  File "<frozen importlib._bootstrap>", line 991, in _find_and_load
  File "<frozen importlib._bootstrap>", line 973, in _find_and_load_unlocked
ModuleNotFoundError: No module named 'gcsfs'

The above exception was the direct cause of the following exception:

Traceback (most recent call last):
  File "/home/airflow/.local/lib/python3.8/site-packages/airflow/decorators/base.py", line 221, in execute
    return_value = super().execute(context)
  File "/home/airflow/.local/lib/python3.8/site-packages/airflow/operators/python.py", line 192, in execute
    return_value = self.execute_callable()
  File "/home/airflow/.local/lib/python3.8/site-packages/airflow/operators/python.py", line 209, in execute_callable
    return self.python_callable(*self.op_args, **self.op_kwargs)
  File "/opt/airflow/dags/quarterly_retrain.py", line 128, in load_transform_data
    df = utils.read_and_clean_data(data_path)
  File "/opt/airflow/modules/utils.py", line 24, in read_and_clean_data
    df = pd.read_csv(file)
  File "/home/airflow/.local/lib/python3.8/site-packages/pandas/io/parsers/readers.py", line 912, in read_csv
    return _read(filepath_or_buffer, kwds)
  File "/home/airflow/.local/lib/python3.8/site-packages/pandas/io/parsers/readers.py", line 577, in _read
    parser = TextFileReader(filepath_or_buffer, **kwds)
  File "/home/airflow/.local/lib/python3.8/site-packages/pandas/io/parsers/readers.py", line 1407, in __init__
    self._engine = self._make_engine(f, self.engine)
  File "/home/airflow/.local/lib/python3.8/site-packages/pandas/io/parsers/readers.py", line 1661, in _make_engine
    self.handles = get_handle(
  File "/home/airflow/.local/lib/python3.8/site-packages/pandas/io/common.py", line 716, in get_handle
    ioargs = _get_filepath_or_buffer(
  File "/home/airflow/.local/lib/python3.8/site-packages/pandas/io/common.py", line 414, in _get_filepath_or_buffer
    file_obj = fsspec.open(
  File "/home/airflow/.local/lib/python3.8/site-packages/fsspec/core.py", line 484, in open
    out = open_files(
  File "/home/airflow/.local/lib/python3.8/site-packages/fsspec/core.py", line 295, in open_files
    fs, fs_token, paths = get_fs_token_paths(
  File "/home/airflow/.local/lib/python3.8/site-packages/fsspec/core.py", line 648, in get_fs_token_paths
    chain = _un_chain(urlpath0, storage_options or {})
  File "/home/airflow/.local/lib/python3.8/site-packages/fsspec/core.py", line 344, in _un_chain
    cls = get_filesystem_class(protocol)
  File "/home/airflow/.local/lib/python3.8/site-packages/fsspec/registry.py", line 244, in get_filesystem_class
    raise ImportError(bit["err"]) from e
ImportError: Please install gcsfs to access Google Storage
[2024-08-12T00:19:03.079+0000] {taskinstance.py:1398} INFO - Marking task as FAILED. dag_id=quarterly_retrain, task_id=load_transform_data, execution_date=20240812T001859, start_date=20240812T001902, end_date=20240812T001903
[2024-08-12T00:19:03.087+0000] {standard_task_runner.py:104} ERROR - Failed to execute job 8 for task load_transform_data (Please install gcsfs to access Google Storage; 2353)
[2024-08-12T00:19:03.097+0000] {local_task_job_runner.py:228} INFO - Task exited with return code 1
[2024-08-12T00:19:03.110+0000] {taskinstance.py:2776} INFO - 0 downstream tasks scheduled from follow-on schedule check
