[2024-08-12T04:17:59.936+0000] {taskinstance.py:1157} INFO - Dependencies all met for dep_context=non-requeueable deps ti=<TaskInstance: quarterly_retrain.run_models manual__2024-08-12T04:17:55.485205+00:00 [queued]>
[2024-08-12T04:17:59.939+0000] {taskinstance.py:1157} INFO - Dependencies all met for dep_context=requeueable deps ti=<TaskInstance: quarterly_retrain.run_models manual__2024-08-12T04:17:55.485205+00:00 [queued]>
[2024-08-12T04:17:59.939+0000] {taskinstance.py:1359} INFO - Starting attempt 1 of 1
[2024-08-12T04:17:59.944+0000] {taskinstance.py:1380} INFO - Executing <Task(_PythonDecoratedOperator): run_models> on 2024-08-12 04:17:55.485205+00:00
[2024-08-12T04:17:59.948+0000] {standard_task_runner.py:57} INFO - Started process 9152 to run task
[2024-08-12T04:17:59.950+0000] {standard_task_runner.py:84} INFO - Running: ['***', 'tasks', 'run', 'quarterly_retrain', 'run_models', 'manual__2024-08-12T04:17:55.485205+00:00', '--job-id', '65', '--raw', '--subdir', 'DAGS_FOLDER/quarterly_retrain.py', '--cfg-path', '/tmp/tmphm5j462z']
[2024-08-12T04:17:59.950+0000] {standard_task_runner.py:85} INFO - Job 65: Subtask run_models
[2024-08-12T04:17:59.972+0000] {task_command.py:415} INFO - Running <TaskInstance: quarterly_retrain.run_models manual__2024-08-12T04:17:55.485205+00:00 [running]> on host f7c751ddefa9
[2024-08-12T04:18:01.960+0000] {taskinstance.py:1660} INFO - Exporting env vars: AIRFLOW_CTX_DAG_OWNER='***' AIRFLOW_CTX_DAG_ID='quarterly_retrain' AIRFLOW_CTX_TASK_ID='run_models' AIRFLOW_CTX_EXECUTION_DATE='2024-08-12T04:17:55.485205+00:00' AIRFLOW_CTX_TRY_NUMBER='1' AIRFLOW_CTX_DAG_RUN_ID='manual__2024-08-12T04:17:55.485205+00:00'
[2024-08-12T04:18:01.990+0000] {taskinstance.py:1935} ERROR - Task failed with exception
Traceback (most recent call last):
  File "/home/airflow/.local/lib/python3.8/site-packages/airflow/decorators/base.py", line 221, in execute
    return_value = super().execute(context)
  File "/home/airflow/.local/lib/python3.8/site-packages/airflow/operators/python.py", line 192, in execute
    return_value = self.execute_callable()
  File "/home/airflow/.local/lib/python3.8/site-packages/airflow/operators/python.py", line 209, in execute_callable
    return self.python_callable(*self.op_args, **self.op_kwargs)
  File "/opt/airflow/dags/quarterly_retrain.py", line 142, in run_models
    X_val = pd.DataFrame.from_dict(data['X_val'])
KeyError: 'X_val'
[2024-08-12T04:18:01.996+0000] {taskinstance.py:1398} INFO - Marking task as FAILED. dag_id=quarterly_retrain, task_id=run_models, execution_date=20240812T041755, start_date=20240812T041759, end_date=20240812T041801
[2024-08-12T04:18:02.001+0000] {standard_task_runner.py:104} ERROR - Failed to execute job 65 for task run_models ('X_val'; 9152)
[2024-08-12T04:18:02.013+0000] {local_task_job_runner.py:228} INFO - Task exited with return code 1
[2024-08-12T04:18:02.025+0000] {taskinstance.py:2776} INFO - 0 downstream tasks scheduled from follow-on schedule check
