[2024-08-12T00:31:04.140+0000] {taskinstance.py:1157} INFO - Dependencies all met for dep_context=non-requeueable deps ti=<TaskInstance: quarterly_retrain.load_transform_data manual__2024-08-12T00:30:51.369441+00:00 [queued]>
[2024-08-12T00:31:04.154+0000] {taskinstance.py:1157} INFO - Dependencies all met for dep_context=requeueable deps ti=<TaskInstance: quarterly_retrain.load_transform_data manual__2024-08-12T00:30:51.369441+00:00 [queued]>
[2024-08-12T00:31:04.154+0000] {taskinstance.py:1359} INFO - Starting attempt 1 of 1
[2024-08-12T00:31:04.171+0000] {taskinstance.py:1380} INFO - Executing <Task(_PythonDecoratedOperator): load_transform_data> on 2024-08-12 00:30:51.369441+00:00
[2024-08-12T00:31:04.227+0000] {standard_task_runner.py:57} INFO - Started process 313 to run task
[2024-08-12T00:31:04.234+0000] {standard_task_runner.py:84} INFO - Running: ['***', 'tasks', 'run', 'quarterly_retrain', 'load_transform_data', 'manual__2024-08-12T00:30:51.369441+00:00', '--job-id', '11', '--raw', '--subdir', 'DAGS_FOLDER/quarterly_retrain.py', '--cfg-path', '/tmp/tmp15p7484w']
[2024-08-12T00:31:04.240+0000] {standard_task_runner.py:85} INFO - Job 11: Subtask load_transform_data
[2024-08-12T00:31:04.338+0000] {task_command.py:415} INFO - Running <TaskInstance: quarterly_retrain.load_transform_data manual__2024-08-12T00:30:51.369441+00:00 [running]> on host f7b9f0f6ca04
[2024-08-12T00:31:04.531+0000] {taskinstance.py:1660} INFO - Exporting env vars: AIRFLOW_CTX_DAG_OWNER='***' AIRFLOW_CTX_DAG_ID='quarterly_retrain' AIRFLOW_CTX_TASK_ID='load_transform_data' AIRFLOW_CTX_EXECUTION_DATE='2024-08-12T00:30:51.369441+00:00' AIRFLOW_CTX_TRY_NUMBER='1' AIRFLOW_CTX_DAG_RUN_ID='manual__2024-08-12T00:30:51.369441+00:00'
[2024-08-12T00:31:05.061+0000] {_metadata.py:207} WARNING - Compute Engine Metadata server unavailable on attempt 1 of 5. Reason: HTTPConnectionPool(host='metadata.google.internal', port=80): Max retries exceeded with url: /computeMetadata/v1/instance/service-accounts/default/?recursive=true (Caused by NewConnectionError('<urllib3.connection.HTTPConnection object at 0xffffa1279190>: Failed to establish a new connection: [Errno -2] Name or service not known'))
[2024-08-12T00:31:05.092+0000] {_metadata.py:207} WARNING - Compute Engine Metadata server unavailable on attempt 2 of 5. Reason: HTTPConnectionPool(host='metadata.google.internal', port=80): Max retries exceeded with url: /computeMetadata/v1/instance/service-accounts/default/?recursive=true (Caused by NewConnectionError('<urllib3.connection.HTTPConnection object at 0xffffa1279310>: Failed to establish a new connection: [Errno -2] Name or service not known'))
[2024-08-12T00:31:05.117+0000] {_metadata.py:207} WARNING - Compute Engine Metadata server unavailable on attempt 3 of 5. Reason: HTTPConnectionPool(host='metadata.google.internal', port=80): Max retries exceeded with url: /computeMetadata/v1/instance/service-accounts/default/?recursive=true (Caused by NewConnectionError('<urllib3.connection.HTTPConnection object at 0xffffa12792b0>: Failed to establish a new connection: [Errno -2] Name or service not known'))
[2024-08-12T00:31:05.136+0000] {_metadata.py:207} WARNING - Compute Engine Metadata server unavailable on attempt 4 of 5. Reason: HTTPConnectionPool(host='metadata.google.internal', port=80): Max retries exceeded with url: /computeMetadata/v1/instance/service-accounts/default/?recursive=true (Caused by NewConnectionError('<urllib3.connection.HTTPConnection object at 0xffffa1279ac0>: Failed to establish a new connection: [Errno -2] Name or service not known'))
[2024-08-12T00:31:05.157+0000] {_metadata.py:207} WARNING - Compute Engine Metadata server unavailable on attempt 5 of 5. Reason: HTTPConnectionPool(host='metadata.google.internal', port=80): Max retries exceeded with url: /computeMetadata/v1/instance/service-accounts/default/?recursive=true (Caused by NewConnectionError('<urllib3.connection.HTTPConnection object at 0xffffa1279f10>: Failed to establish a new connection: [Errno -2] Name or service not known'))
[2024-08-12T00:31:05.370+0000] {retry.py:160} ERROR - _request non-retriable exception: Anonymous caller does not have storage.objects.get access to the Google Cloud Storage object. Permission 'storage.objects.get' denied on resource (or it may not exist)., 401
Traceback (most recent call last):
  File "/home/airflow/.local/lib/python3.8/site-packages/gcsfs/retry.py", line 126, in retry_request
    return await func(*args, **kwargs)
  File "/home/airflow/.local/lib/python3.8/site-packages/gcsfs/core.py", line 440, in _request
    validate_response(status, contents, path, args)
  File "/home/airflow/.local/lib/python3.8/site-packages/gcsfs/retry.py", line 113, in validate_response
    raise HttpError(error)
gcsfs.retry.HttpError: Anonymous caller does not have storage.objects.get access to the Google Cloud Storage object. Permission 'storage.objects.get' denied on resource (or it may not exist)., 401
[2024-08-12T00:31:05.390+0000] {taskinstance.py:1935} ERROR - Task failed with exception
Traceback (most recent call last):
  File "/home/airflow/.local/lib/python3.8/site-packages/airflow/decorators/base.py", line 221, in execute
    return_value = super().execute(context)
  File "/home/airflow/.local/lib/python3.8/site-packages/airflow/operators/python.py", line 192, in execute
    return_value = self.execute_callable()
  File "/home/airflow/.local/lib/python3.8/site-packages/airflow/operators/python.py", line 209, in execute_callable
    return self.python_callable(*self.op_args, **self.op_kwargs)
  File "/opt/airflow/dags/quarterly_retrain.py", line 128, in load_transform_data
    df = utils.read_and_clean_data(data_path)
  File "/opt/airflow/modules/utils.py", line 24, in read_and_clean_data
    df = pd.read_csv(file)
  File "/home/airflow/.local/lib/python3.8/site-packages/pandas/io/parsers/readers.py", line 912, in read_csv
    return _read(filepath_or_buffer, kwds)
  File "/home/airflow/.local/lib/python3.8/site-packages/pandas/io/parsers/readers.py", line 577, in _read
    parser = TextFileReader(filepath_or_buffer, **kwds)
  File "/home/airflow/.local/lib/python3.8/site-packages/pandas/io/parsers/readers.py", line 1407, in __init__
    self._engine = self._make_engine(f, self.engine)
  File "/home/airflow/.local/lib/python3.8/site-packages/pandas/io/parsers/readers.py", line 1661, in _make_engine
    self.handles = get_handle(
  File "/home/airflow/.local/lib/python3.8/site-packages/pandas/io/common.py", line 716, in get_handle
    ioargs = _get_filepath_or_buffer(
  File "/home/airflow/.local/lib/python3.8/site-packages/pandas/io/common.py", line 414, in _get_filepath_or_buffer
    file_obj = fsspec.open(
  File "/home/airflow/.local/lib/python3.8/site-packages/fsspec/core.py", line 147, in open
    return self.__enter__()
  File "/home/airflow/.local/lib/python3.8/site-packages/fsspec/core.py", line 105, in __enter__
    f = self.fs.open(self.path, mode=mode)
  File "/home/airflow/.local/lib/python3.8/site-packages/fsspec/spec.py", line 1303, in open
    f = self._open(
  File "/home/airflow/.local/lib/python3.8/site-packages/gcsfs/core.py", line 1584, in _open
    return GCSFile(
  File "/home/airflow/.local/lib/python3.8/site-packages/gcsfs/core.py", line 1749, in __init__
    super().__init__(
  File "/home/airflow/.local/lib/python3.8/site-packages/fsspec/spec.py", line 1742, in __init__
    self.size = self.details["size"]
  File "/home/airflow/.local/lib/python3.8/site-packages/gcsfs/core.py", line 1785, in details
    self._details = self.fs.info(self.path, generation=self.generation)
  File "/home/airflow/.local/lib/python3.8/site-packages/fsspec/asyn.py", line 118, in wrapper
    return sync(self.loop, func, *args, **kwargs)
  File "/home/airflow/.local/lib/python3.8/site-packages/fsspec/asyn.py", line 103, in sync
    raise return_result
  File "/home/airflow/.local/lib/python3.8/site-packages/fsspec/asyn.py", line 56, in _runner
    result[0] = await coro
  File "/home/airflow/.local/lib/python3.8/site-packages/gcsfs/core.py", line 994, in _info
    exact = await self._get_object(path)
  File "/home/airflow/.local/lib/python3.8/site-packages/gcsfs/core.py", line 527, in _get_object
    res = await self._call(
  File "/home/airflow/.local/lib/python3.8/site-packages/gcsfs/core.py", line 447, in _call
    status, headers, info, contents = await self._request(
  File "/home/airflow/.local/lib/python3.8/site-packages/decorator.py", line 221, in fun
    return await caller(func, *(extras + args), **kw)
  File "/home/airflow/.local/lib/python3.8/site-packages/gcsfs/retry.py", line 161, in retry_request
    raise e
  File "/home/airflow/.local/lib/python3.8/site-packages/gcsfs/retry.py", line 126, in retry_request
    return await func(*args, **kwargs)
  File "/home/airflow/.local/lib/python3.8/site-packages/gcsfs/core.py", line 440, in _request
    validate_response(status, contents, path, args)
  File "/home/airflow/.local/lib/python3.8/site-packages/gcsfs/retry.py", line 113, in validate_response
    raise HttpError(error)
gcsfs.retry.HttpError: Anonymous caller does not have storage.objects.get access to the Google Cloud Storage object. Permission 'storage.objects.get' denied on resource (or it may not exist)., 401
[2024-08-12T00:31:05.449+0000] {taskinstance.py:1398} INFO - Marking task as FAILED. dag_id=quarterly_retrain, task_id=load_transform_data, execution_date=20240812T003051, start_date=20240812T003104, end_date=20240812T003105
[2024-08-12T00:31:05.526+0000] {standard_task_runner.py:104} ERROR - Failed to execute job 11 for task load_transform_data (Anonymous caller does not have storage.objects.get access to the Google Cloud Storage object. Permission 'storage.objects.get' denied on resource (or it may not exist)., 401; 313)
[2024-08-12T00:31:05.568+0000] {local_task_job_runner.py:228} INFO - Task exited with return code 1
[2024-08-12T00:31:05.690+0000] {taskinstance.py:2776} INFO - 0 downstream tasks scheduled from follow-on schedule check
