[2024-08-12T18:04:49.313+0000] {taskinstance.py:1157} INFO - Dependencies all met for dep_context=non-requeueable deps ti=<TaskInstance: monthly_monitor.create_table scheduled__2024-02-01T00:00:00+00:00 [queued]>
[2024-08-12T18:04:49.336+0000] {taskinstance.py:1157} INFO - Dependencies all met for dep_context=requeueable deps ti=<TaskInstance: monthly_monitor.create_table scheduled__2024-02-01T00:00:00+00:00 [queued]>
[2024-08-12T18:04:49.362+0000] {taskinstance.py:1359} INFO - Starting attempt 1 of 1
[2024-08-12T18:04:49.551+0000] {taskinstance.py:1380} INFO - Executing <Task(_PythonDecoratedOperator): create_table> on 2024-02-01 00:00:00+00:00
[2024-08-12T18:04:49.588+0000] {standard_task_runner.py:57} INFO - Started process 7851 to run task
[2024-08-12T18:04:49.607+0000] {standard_task_runner.py:84} INFO - Running: ['***', 'tasks', 'run', 'monthly_monitor', 'create_table', 'scheduled__2024-02-01T00:00:00+00:00', '--job-id', '212', '--raw', '--subdir', 'DAGS_FOLDER/monitor.py', '--cfg-path', '/tmp/tmp6edbcrcq']
[2024-08-12T18:04:49.626+0000] {standard_task_runner.py:85} INFO - Job 212: Subtask create_table
[2024-08-12T18:04:49.866+0000] {task_command.py:415} INFO - Running <TaskInstance: monthly_monitor.create_table scheduled__2024-02-01T00:00:00+00:00 [running]> on host a9166c5dc5ae
[2024-08-12T18:04:50.026+0000] {taskinstance.py:1660} INFO - Exporting env vars: AIRFLOW_CTX_DAG_OWNER='***' AIRFLOW_CTX_DAG_ID='monthly_monitor' AIRFLOW_CTX_TASK_ID='create_table' AIRFLOW_CTX_EXECUTION_DATE='2024-02-01T00:00:00+00:00' AIRFLOW_CTX_TRY_NUMBER='1' AIRFLOW_CTX_DAG_RUN_ID='scheduled__2024-02-01T00:00:00+00:00'
[2024-08-12T18:04:50.029+0000] {taskinstance.py:1935} ERROR - Task failed with exception
Traceback (most recent call last):
  File "/home/airflow/.local/lib/python3.8/site-packages/airflow/decorators/base.py", line 221, in execute
    return_value = super().execute(context)
  File "/home/airflow/.local/lib/python3.8/site-packages/airflow/operators/python.py", line 192, in execute
    return_value = self.execute_callable()
  File "/home/airflow/.local/lib/python3.8/site-packages/airflow/operators/python.py", line 209, in execute_callable
    return self.python_callable(*self.op_args, **self.op_kwargs)
  File "/opt/airflow/dags/monitor.py", line 44, in create_table
    conn = psycopg2.connect(**conn_params)
  File "/home/airflow/.local/lib/python3.8/site-packages/psycopg2/__init__.py", line 122, in connect
    conn = _connect(dsn, connection_factory=connection_factory, **kwasync)
psycopg2.OperationalError: connection to server at "localhost" (127.0.0.1), port 5432 failed: Connection refused
	Is the server running on that host and accepting TCP/IP connections?
connection to server at "localhost" (::1), port 5432 failed: Cannot assign requested address
	Is the server running on that host and accepting TCP/IP connections?

[2024-08-12T18:04:50.046+0000] {taskinstance.py:1398} INFO - Marking task as FAILED. dag_id=monthly_monitor, task_id=create_table, execution_date=20240201T000000, start_date=20240812T180449, end_date=20240812T180450
[2024-08-12T18:04:50.119+0000] {standard_task_runner.py:104} ERROR - Failed to execute job 212 for task create_table (connection to server at "localhost" (127.0.0.1), port 5432 failed: Connection refused
	Is the server running on that host and accepting TCP/IP connections?
connection to server at "localhost" (::1), port 5432 failed: Cannot assign requested address
	Is the server running on that host and accepting TCP/IP connections?
; 7851)
[2024-08-12T18:04:50.170+0000] {local_task_job_runner.py:228} INFO - Task exited with return code 1
[2024-08-12T18:04:50.202+0000] {taskinstance.py:2776} INFO - 0 downstream tasks scheduled from follow-on schedule check
