[2024-08-12T17:08:27.861+0000] {taskinstance.py:1157} INFO - Dependencies all met for dep_context=non-requeueable deps ti=<TaskInstance: monthly_prediction.predict_and_save manual__2024-08-12T17:08:23.420182+00:00 [queued]>
[2024-08-12T17:08:27.866+0000] {taskinstance.py:1157} INFO - Dependencies all met for dep_context=requeueable deps ti=<TaskInstance: monthly_prediction.predict_and_save manual__2024-08-12T17:08:23.420182+00:00 [queued]>
[2024-08-12T17:08:27.866+0000] {taskinstance.py:1359} INFO - Starting attempt 1 of 1
[2024-08-12T17:08:27.875+0000] {taskinstance.py:1380} INFO - Executing <Task(_PythonDecoratedOperator): predict_and_save> on 2024-08-12 17:08:23.420182+00:00
[2024-08-12T17:08:27.880+0000] {standard_task_runner.py:57} INFO - Started process 26545 to run task
[2024-08-12T17:08:27.883+0000] {standard_task_runner.py:84} INFO - Running: ['***', 'tasks', 'run', 'monthly_prediction', 'predict_and_save', 'manual__2024-08-12T17:08:23.420182+00:00', '--job-id', '169', '--raw', '--subdir', 'DAGS_FOLDER/monitor.py', '--cfg-path', '/tmp/tmpwk04g547']
[2024-08-12T17:08:27.885+0000] {standard_task_runner.py:85} INFO - Job 169: Subtask predict_and_save
[2024-08-12T17:08:27.924+0000] {task_command.py:415} INFO - Running <TaskInstance: monthly_prediction.predict_and_save manual__2024-08-12T17:08:23.420182+00:00 [running]> on host fa284eed0508
[2024-08-12T17:08:28.110+0000] {taskinstance.py:1660} INFO - Exporting env vars: AIRFLOW_CTX_DAG_OWNER='***' AIRFLOW_CTX_DAG_ID='monthly_prediction' AIRFLOW_CTX_TASK_ID='predict_and_save' AIRFLOW_CTX_EXECUTION_DATE='2024-08-12T17:08:23.420182+00:00' AIRFLOW_CTX_TRY_NUMBER='1' AIRFLOW_CTX_DAG_RUN_ID='manual__2024-08-12T17:08:23.420182+00:00'
[2024-08-12T17:08:28.111+0000] {taskinstance.py:1935} ERROR - Task failed with exception
Traceback (most recent call last):
  File "/home/airflow/.local/lib/python3.8/site-packages/airflow/decorators/base.py", line 221, in execute
    return_value = super().execute(context)
  File "/home/airflow/.local/lib/python3.8/site-packages/airflow/operators/python.py", line 192, in execute
    return_value = self.execute_callable()
  File "/home/airflow/.local/lib/python3.8/site-packages/airflow/operators/python.py", line 209, in execute_callable
    return self.python_callable(*self.op_args, **self.op_kwargs)
  File "/opt/airflow/dags/monitor.py", line 34, in predict_and_save
    model = utils.load_model(client, 'RandomForestClassifier', '1')
TypeError: load_model() takes 2 positional arguments but 3 were given
[2024-08-12T17:08:28.116+0000] {taskinstance.py:1398} INFO - Marking task as FAILED. dag_id=monthly_prediction, task_id=predict_and_save, execution_date=20240812T170823, start_date=20240812T170827, end_date=20240812T170828
[2024-08-12T17:08:28.123+0000] {standard_task_runner.py:104} ERROR - Failed to execute job 169 for task predict_and_save (load_model() takes 2 positional arguments but 3 were given; 26545)
[2024-08-12T17:08:28.145+0000] {local_task_job_runner.py:228} INFO - Task exited with return code 1
[2024-08-12T17:08:28.155+0000] {taskinstance.py:2776} INFO - 0 downstream tasks scheduled from follow-on schedule check
