[2024-08-12T17:11:37.433+0000] {taskinstance.py:1157} INFO - Dependencies all met for dep_context=non-requeueable deps ti=<TaskInstance: monthly_prediction.predict_and_save manual__2024-08-12T17:11:32.019482+00:00 [queued]>
[2024-08-12T17:11:37.437+0000] {taskinstance.py:1157} INFO - Dependencies all met for dep_context=requeueable deps ti=<TaskInstance: monthly_prediction.predict_and_save manual__2024-08-12T17:11:32.019482+00:00 [queued]>
[2024-08-12T17:11:37.437+0000] {taskinstance.py:1359} INFO - Starting attempt 1 of 1
[2024-08-12T17:11:37.443+0000] {taskinstance.py:1380} INFO - Executing <Task(_PythonDecoratedOperator): predict_and_save> on 2024-08-12 17:11:32.019482+00:00
[2024-08-12T17:11:37.446+0000] {standard_task_runner.py:57} INFO - Started process 324 to run task
[2024-08-12T17:11:37.448+0000] {standard_task_runner.py:84} INFO - Running: ['***', 'tasks', 'run', 'monthly_prediction', 'predict_and_save', 'manual__2024-08-12T17:11:32.019482+00:00', '--job-id', '175', '--raw', '--subdir', 'DAGS_FOLDER/monitor.py', '--cfg-path', '/tmp/tmp2mcxk3go']
[2024-08-12T17:11:37.449+0000] {standard_task_runner.py:85} INFO - Job 175: Subtask predict_and_save
[2024-08-12T17:11:37.471+0000] {task_command.py:415} INFO - Running <TaskInstance: monthly_prediction.predict_and_save manual__2024-08-12T17:11:32.019482+00:00 [running]> on host a9166c5dc5ae
[2024-08-12T17:11:37.633+0000] {taskinstance.py:1660} INFO - Exporting env vars: AIRFLOW_CTX_DAG_OWNER='***' AIRFLOW_CTX_DAG_ID='monthly_prediction' AIRFLOW_CTX_TASK_ID='predict_and_save' AIRFLOW_CTX_EXECUTION_DATE='2024-08-12T17:11:32.019482+00:00' AIRFLOW_CTX_TRY_NUMBER='1' AIRFLOW_CTX_DAG_RUN_ID='manual__2024-08-12T17:11:32.019482+00:00'
[2024-08-12T17:11:37.634+0000] {taskinstance.py:1935} ERROR - Task failed with exception
Traceback (most recent call last):
  File "/home/airflow/.local/lib/python3.8/site-packages/airflow/decorators/base.py", line 221, in execute
    return_value = super().execute(context)
  File "/home/airflow/.local/lib/python3.8/site-packages/airflow/operators/python.py", line 192, in execute
    return_value = self.execute_callable()
  File "/home/airflow/.local/lib/python3.8/site-packages/airflow/operators/python.py", line 209, in execute_callable
    return self.python_callable(*self.op_args, **self.op_kwargs)
  File "/opt/airflow/dags/monitor.py", line 34, in predict_and_save
    model = utils.load_model(client, 'RandomForestClassifier', '1')
TypeError: load_model() takes 2 positional arguments but 3 were given
[2024-08-12T17:11:37.638+0000] {taskinstance.py:1398} INFO - Marking task as FAILED. dag_id=monthly_prediction, task_id=predict_and_save, execution_date=20240812T171132, start_date=20240812T171137, end_date=20240812T171137
[2024-08-12T17:11:37.644+0000] {standard_task_runner.py:104} ERROR - Failed to execute job 175 for task predict_and_save (load_model() takes 2 positional arguments but 3 were given; 324)
[2024-08-12T17:11:37.672+0000] {local_task_job_runner.py:228} INFO - Task exited with return code 1
[2024-08-12T17:11:37.681+0000] {taskinstance.py:2776} INFO - 0 downstream tasks scheduled from follow-on schedule check
