[2024-08-12T20:06:41.514+0000] {taskinstance.py:1157} INFO - Dependencies all met for dep_context=non-requeueable deps ti=<TaskInstance: monthly_prediction.simulate_and_prepare_data manual__2024-08-12T20:06:39.577730+00:00 [queued]>
[2024-08-12T20:06:41.518+0000] {taskinstance.py:1157} INFO - Dependencies all met for dep_context=requeueable deps ti=<TaskInstance: monthly_prediction.simulate_and_prepare_data manual__2024-08-12T20:06:39.577730+00:00 [queued]>
[2024-08-12T20:06:41.519+0000] {taskinstance.py:1359} INFO - Starting attempt 1 of 1
[2024-08-12T20:06:41.526+0000] {taskinstance.py:1380} INFO - Executing <Task(_PythonDecoratedOperator): simulate_and_prepare_data> on 2024-08-12 20:06:39.577730+00:00
[2024-08-12T20:06:41.533+0000] {standard_task_runner.py:57} INFO - Started process 12141 to run task
[2024-08-12T20:06:41.536+0000] {standard_task_runner.py:84} INFO - Running: ['***', 'tasks', 'run', 'monthly_prediction', 'simulate_and_prepare_data', 'manual__2024-08-12T20:06:39.577730+00:00', '--job-id', '853', '--raw', '--subdir', 'DAGS_FOLDER/monthly_prediction.py', '--cfg-path', '/tmp/tmpr84t92k1']
[2024-08-12T20:06:41.540+0000] {standard_task_runner.py:85} INFO - Job 853: Subtask simulate_and_prepare_data
[2024-08-12T20:06:41.824+0000] {task_command.py:415} INFO - Running <TaskInstance: monthly_prediction.simulate_and_prepare_data manual__2024-08-12T20:06:39.577730+00:00 [running]> on host a9166c5dc5ae
[2024-08-12T20:06:41.884+0000] {taskinstance.py:1660} INFO - Exporting env vars: AIRFLOW_CTX_DAG_OWNER='***' AIRFLOW_CTX_DAG_ID='monthly_prediction' AIRFLOW_CTX_TASK_ID='simulate_and_prepare_data' AIRFLOW_CTX_EXECUTION_DATE='2024-08-12T20:06:39.577730+00:00' AIRFLOW_CTX_TRY_NUMBER='1' AIRFLOW_CTX_DAG_RUN_ID='manual__2024-08-12T20:06:39.577730+00:00'
[2024-08-12T20:06:41.885+0000] {taskinstance.py:1935} ERROR - Task failed with exception
Traceback (most recent call last):
  File "/home/airflow/.local/lib/python3.8/site-packages/airflow/decorators/base.py", line 221, in execute
    return_value = super().execute(context)
  File "/home/airflow/.local/lib/python3.8/site-packages/airflow/operators/python.py", line 192, in execute
    return_value = self.execute_callable()
  File "/home/airflow/.local/lib/python3.8/site-packages/airflow/operators/python.py", line 209, in execute_callable
    return self.python_callable(*self.op_args, **self.op_kwargs)
  File "/opt/airflow/dags/monthly_prediction.py", line 35, in simulate_and_prepare_data
    seed = int(datetime.datetime.now().timestamp()) % 10000
AttributeError: type object 'datetime.datetime' has no attribute 'datetime'
[2024-08-12T20:06:41.892+0000] {taskinstance.py:1398} INFO - Marking task as FAILED. dag_id=monthly_prediction, task_id=simulate_and_prepare_data, execution_date=20240812T200639, start_date=20240812T200641, end_date=20240812T200641
[2024-08-12T20:06:41.898+0000] {standard_task_runner.py:104} ERROR - Failed to execute job 853 for task simulate_and_prepare_data (type object 'datetime.datetime' has no attribute 'datetime'; 12141)
[2024-08-12T20:06:41.940+0000] {local_task_job_runner.py:228} INFO - Task exited with return code 1
[2024-08-12T20:06:42.061+0000] {taskinstance.py:2776} INFO - 0 downstream tasks scheduled from follow-on schedule check
