[2024-08-12T03:39:53.806+0000] {taskinstance.py:1157} INFO - Dependencies all met for dep_context=non-requeueable deps ti=<TaskInstance: quarterly_retrain.test manual__2024-08-12T03:39:51.659779+00:00 [queued]>
[2024-08-12T03:39:53.810+0000] {taskinstance.py:1157} INFO - Dependencies all met for dep_context=requeueable deps ti=<TaskInstance: quarterly_retrain.test manual__2024-08-12T03:39:51.659779+00:00 [queued]>
[2024-08-12T03:39:53.810+0000] {taskinstance.py:1359} INFO - Starting attempt 1 of 1
[2024-08-12T03:39:53.817+0000] {taskinstance.py:1380} INFO - Executing <Task(_PythonDecoratedOperator): test> on 2024-08-12 03:39:51.659779+00:00
[2024-08-12T03:39:53.823+0000] {standard_task_runner.py:57} INFO - Started process 5651 to run task
[2024-08-12T03:39:53.825+0000] {standard_task_runner.py:84} INFO - Running: ['***', 'tasks', 'run', 'quarterly_retrain', 'test', 'manual__2024-08-12T03:39:51.659779+00:00', '--job-id', '30', '--raw', '--subdir', 'DAGS_FOLDER/quarterly_retrain.py', '--cfg-path', '/tmp/tmpzsnmx_40']
[2024-08-12T03:39:53.825+0000] {standard_task_runner.py:85} INFO - Job 30: Subtask test
[2024-08-12T03:39:53.850+0000] {task_command.py:415} INFO - Running <TaskInstance: quarterly_retrain.test manual__2024-08-12T03:39:51.659779+00:00 [running]> on host f7c751ddefa9
[2024-08-12T03:39:53.887+0000] {taskinstance.py:1660} INFO - Exporting env vars: AIRFLOW_CTX_DAG_OWNER='***' AIRFLOW_CTX_DAG_ID='quarterly_retrain' AIRFLOW_CTX_TASK_ID='test' AIRFLOW_CTX_EXECUTION_DATE='2024-08-12T03:39:51.659779+00:00' AIRFLOW_CTX_TRY_NUMBER='1' AIRFLOW_CTX_DAG_RUN_ID='manual__2024-08-12T03:39:51.659779+00:00'
[2024-08-12T03:39:53.889+0000] {taskinstance.py:1935} ERROR - Task failed with exception
Traceback (most recent call last):
  File "/home/airflow/.local/lib/python3.8/site-packages/airflow/decorators/base.py", line 221, in execute
    return_value = super().execute(context)
  File "/home/airflow/.local/lib/python3.8/site-packages/airflow/operators/python.py", line 192, in execute
    return_value = self.execute_callable()
  File "/home/airflow/.local/lib/python3.8/site-packages/airflow/operators/python.py", line 209, in execute_callable
    return self.python_callable(*self.op_args, **self.op_kwargs)
  File "/opt/airflow/dags/quarterly_retrain.py", line 174, in test
    df = pd.read_csv(path)
NameError: name 'pd' is not defined
[2024-08-12T03:39:53.894+0000] {taskinstance.py:1398} INFO - Marking task as FAILED. dag_id=quarterly_retrain, task_id=test, execution_date=20240812T033951, start_date=20240812T033953, end_date=20240812T033953
[2024-08-12T03:39:53.898+0000] {standard_task_runner.py:104} ERROR - Failed to execute job 30 for task test (name 'pd' is not defined; 5651)
[2024-08-12T03:39:53.924+0000] {local_task_job_runner.py:228} INFO - Task exited with return code 1
[2024-08-12T03:39:53.935+0000] {taskinstance.py:2776} INFO - 0 downstream tasks scheduled from follow-on schedule check
